[32mINFO[0m:     Uvicorn running on [1mhttp://0.0.0.0:9000[0m (Press CTRL+C to quit)
[32mINFO[0m:     Started reloader process [[36m[1m46[0m] using [36m[1mstatreload[0m
Process SpawnProcess-1:
Traceback (most recent call last):
  File "/root/.local/share/virtualenvs/app-4PlAip0Q/lib/python3.9/site-packages/sqlalchemy/engine/base.py", line 2336, in _wrap_pool_connect
    return fn()
  File "/root/.local/share/virtualenvs/app-4PlAip0Q/lib/python3.9/site-packages/sqlalchemy/pool/base.py", line 364, in connect
    return _ConnectionFairy._checkout(self)
  File "/root/.local/share/virtualenvs/app-4PlAip0Q/lib/python3.9/site-packages/sqlalchemy/pool/base.py", line 778, in _checkout
    fairy = _ConnectionRecord.checkout(pool)
  File "/root/.local/share/virtualenvs/app-4PlAip0Q/lib/python3.9/site-packages/sqlalchemy/pool/base.py", line 495, in checkout
    rec = pool._do_get()
  File "/root/.local/share/virtualenvs/app-4PlAip0Q/lib/python3.9/site-packages/sqlalchemy/pool/impl.py", line 140, in _do_get
    self._dec_overflow()
  File "/root/.local/share/virtualenvs/app-4PlAip0Q/lib/python3.9/site-packages/sqlalchemy/util/langhelpers.py", line 68, in __exit__
    compat.raise_(
  File "/root/.local/share/virtualenvs/app-4PlAip0Q/lib/python3.9/site-packages/sqlalchemy/util/compat.py", line 182, in raise_
    raise exception
  File "/root/.local/share/virtualenvs/app-4PlAip0Q/lib/python3.9/site-packages/sqlalchemy/pool/impl.py", line 137, in _do_get
    return self._create_connection()
  File "/root/.local/share/virtualenvs/app-4PlAip0Q/lib/python3.9/site-packages/sqlalchemy/pool/base.py", line 309, in _create_connection
    return _ConnectionRecord(self)
  File "/root/.local/share/virtualenvs/app-4PlAip0Q/lib/python3.9/site-packages/sqlalchemy/pool/base.py", line 440, in __init__
    self.__connect(first_connect_check=True)
  File "/root/.local/share/virtualenvs/app-4PlAip0Q/lib/python3.9/site-packages/sqlalchemy/pool/base.py", line 661, in __connect
    pool.logger.debug("Error on connect(): %s", e)
  File "/root/.local/share/virtualenvs/app-4PlAip0Q/lib/python3.9/site-packages/sqlalchemy/util/langhelpers.py", line 68, in __exit__
    compat.raise_(
  File "/root/.local/share/virtualenvs/app-4PlAip0Q/lib/python3.9/site-packages/sqlalchemy/util/compat.py", line 182, in raise_
    raise exception
  File "/root/.local/share/virtualenvs/app-4PlAip0Q/lib/python3.9/site-packages/sqlalchemy/pool/base.py", line 656, in __connect
    connection = pool._invoke_creator(self)
  File "/root/.local/share/virtualenvs/app-4PlAip0Q/lib/python3.9/site-packages/sqlalchemy/engine/strategies.py", line 114, in connect
    return dialect.connect(*cargs, **cparams)
  File "/root/.local/share/virtualenvs/app-4PlAip0Q/lib/python3.9/site-packages/sqlalchemy/engine/default.py", line 508, in connect
    return self.dbapi.connect(*cargs, **cparams)
  File "/root/.local/share/virtualenvs/app-4PlAip0Q/lib/python3.9/site-packages/psycopg2/__init__.py", line 127, in connect
    conn = _connect(dsn, connection_factory=connection_factory, **kwasync)
psycopg2.OperationalError: FATAL:  database "news" does not exist


The above exception was the direct cause of the following exception:

Traceback (most recent call last):
  File "/usr/local/lib/python3.9/multiprocessing/process.py", line 315, in _bootstrap
    self.run()
  File "/usr/local/lib/python3.9/multiprocessing/process.py", line 108, in run
    self._target(*self._args, **self._kwargs)
  File "/root/.local/share/virtualenvs/app-4PlAip0Q/lib/python3.9/site-packages/uvicorn/subprocess.py", line 61, in subprocess_started
    target(sockets=sockets)
  File "/root/.local/share/virtualenvs/app-4PlAip0Q/lib/python3.9/site-packages/uvicorn/server.py", line 49, in run
    loop.run_until_complete(self.serve(sockets=sockets))
  File "/usr/local/lib/python3.9/asyncio/base_events.py", line 642, in run_until_complete
    return future.result()
  File "/root/.local/share/virtualenvs/app-4PlAip0Q/lib/python3.9/site-packages/uvicorn/server.py", line 56, in serve
    config.load()
  File "/root/.local/share/virtualenvs/app-4PlAip0Q/lib/python3.9/site-packages/uvicorn/config.py", line 308, in load
    self.loaded_app = import_from_string(self.app)
  File "/root/.local/share/virtualenvs/app-4PlAip0Q/lib/python3.9/site-packages/uvicorn/importer.py", line 20, in import_from_string
    module = importlib.import_module(module_str)
  File "/usr/local/lib/python3.9/importlib/__init__.py", line 127, in import_module
    return _bootstrap._gcd_import(name[level:], package, level)
  File "<frozen importlib._bootstrap>", line 1030, in _gcd_import
  File "<frozen importlib._bootstrap>", line 1007, in _find_and_load
  File "<frozen importlib._bootstrap>", line 986, in _find_and_load_unlocked
  File "<frozen importlib._bootstrap>", line 680, in _load_unlocked
  File "<frozen importlib._bootstrap_external>", line 850, in exec_module
  File "<frozen importlib._bootstrap>", line 228, in _call_with_frames_removed
  File "/app/./main.py", line 46, in <module>
    metadata.create_all(engine)
  File "/root/.local/share/virtualenvs/app-4PlAip0Q/lib/python3.9/site-packages/sqlalchemy/sql/schema.py", line 4664, in create_all
    bind._run_visitor(
  File "/root/.local/share/virtualenvs/app-4PlAip0Q/lib/python3.9/site-packages/sqlalchemy/engine/base.py", line 2094, in _run_visitor
    with self._optional_conn_ctx_manager(connection) as conn:
  File "/usr/local/lib/python3.9/contextlib.py", line 119, in __enter__
    return next(self.gen)
  File "/root/.local/share/virtualenvs/app-4PlAip0Q/lib/python3.9/site-packages/sqlalchemy/engine/base.py", line 2086, in _optional_conn_ctx_manager
    with self._contextual_connect() as conn:
  File "/root/.local/share/virtualenvs/app-4PlAip0Q/lib/python3.9/site-packages/sqlalchemy/engine/base.py", line 2302, in _contextual_connect
    self._wrap_pool_connect(self.pool.connect, None),
  File "/root/.local/share/virtualenvs/app-4PlAip0Q/lib/python3.9/site-packages/sqlalchemy/engine/base.py", line 2339, in _wrap_pool_connect
    Connection._handle_dbapi_exception_noconnection(
  File "/root/.local/share/virtualenvs/app-4PlAip0Q/lib/python3.9/site-packages/sqlalchemy/engine/base.py", line 1583, in _handle_dbapi_exception_noconnection
    util.raise_(
  File "/root/.local/share/virtualenvs/app-4PlAip0Q/lib/python3.9/site-packages/sqlalchemy/util/compat.py", line 182, in raise_
    raise exception
  File "/root/.local/share/virtualenvs/app-4PlAip0Q/lib/python3.9/site-packages/sqlalchemy/engine/base.py", line 2336, in _wrap_pool_connect
    return fn()
  File "/root/.local/share/virtualenvs/app-4PlAip0Q/lib/python3.9/site-packages/sqlalchemy/pool/base.py", line 364, in connect
    return _ConnectionFairy._checkout(self)
  File "/root/.local/share/virtualenvs/app-4PlAip0Q/lib/python3.9/site-packages/sqlalchemy/pool/base.py", line 778, in _checkout
    fairy = _ConnectionRecord.checkout(pool)
  File "/root/.local/share/virtualenvs/app-4PlAip0Q/lib/python3.9/site-packages/sqlalchemy/pool/base.py", line 495, in checkout
    rec = pool._do_get()
  File "/root/.local/share/virtualenvs/app-4PlAip0Q/lib/python3.9/site-packages/sqlalchemy/pool/impl.py", line 140, in _do_get
    self._dec_overflow()
  File "/root/.local/share/virtualenvs/app-4PlAip0Q/lib/python3.9/site-packages/sqlalchemy/util/langhelpers.py", line 68, in __exit__
    compat.raise_(
  File "/root/.local/share/virtualenvs/app-4PlAip0Q/lib/python3.9/site-packages/sqlalchemy/util/compat.py", line 182, in raise_
    raise exception
  File "/root/.local/share/virtualenvs/app-4PlAip0Q/lib/python3.9/site-packages/sqlalchemy/pool/impl.py", line 137, in _do_get
    return self._create_connection()
  File "/root/.local/share/virtualenvs/app-4PlAip0Q/lib/python3.9/site-packages/sqlalchemy/pool/base.py", line 309, in _create_connection
    return _ConnectionRecord(self)
  File "/root/.local/share/virtualenvs/app-4PlAip0Q/lib/python3.9/site-packages/sqlalchemy/pool/base.py", line 440, in __init__
    self.__connect(first_connect_check=True)
  File "/root/.local/share/virtualenvs/app-4PlAip0Q/lib/python3.9/site-packages/sqlalchemy/pool/base.py", line 661, in __connect
    pool.logger.debug("Error on connect(): %s", e)
  File "/root/.local/share/virtualenvs/app-4PlAip0Q/lib/python3.9/site-packages/sqlalchemy/util/langhelpers.py", line 68, in __exit__
    compat.raise_(
  File "/root/.local/share/virtualenvs/app-4PlAip0Q/lib/python3.9/site-packages/sqlalchemy/util/compat.py", line 182, in raise_
    raise exception
  File "/root/.local/share/virtualenvs/app-4PlAip0Q/lib/python3.9/site-packages/sqlalchemy/pool/base.py", line 656, in __connect
    connection = pool._invoke_creator(self)
  File "/root/.local/share/virtualenvs/app-4PlAip0Q/lib/python3.9/site-packages/sqlalchemy/engine/strategies.py", line 114, in connect
    return dialect.connect(*cargs, **cparams)
  File "/root/.local/share/virtualenvs/app-4PlAip0Q/lib/python3.9/site-packages/sqlalchemy/engine/default.py", line 508, in connect
    return self.dbapi.connect(*cargs, **cparams)
  File "/root/.local/share/virtualenvs/app-4PlAip0Q/lib/python3.9/site-packages/psycopg2/__init__.py", line 127, in connect
    conn = _connect(dsn, connection_factory=connection_factory, **kwasync)
sqlalchemy.exc.OperationalError: (psycopg2.OperationalError) FATAL:  database "news" does not exist

(Background on this error at: http://sqlalche.me/e/13/e3q8)
[32mINFO[0m:     Stopping reloader process [[36m[1m46[0m]
